[2021-01-23 12:59:30,525] ERROR: Internal Server Error: /api/search
Traceback (most recent call last):
  File "/Users/neo1/PycharmProjects/vec4irltr/venv/lib/python3.8/site-packages/django/core/handlers/exception.py", line 34, in inner
    response = get_response(request)
  File "/Users/neo1/PycharmProjects/vec4irltr/venv/lib/python3.8/site-packages/django/core/handlers/base.py", line 126, in _get_response
    response = self.process_exception_by_middleware(e, request)
  File "/Users/neo1/PycharmProjects/vec4irltr/venv/lib/python3.8/site-packages/django/core/handlers/base.py", line 124, in _get_response
    response = wrapped_callback(request, *callback_args, **callback_kwargs)
  File "/Users/neo1/PycharmProjects/vec4irltr/venv/lib/python3.8/site-packages/ninja/operation.py", line 227, in _sync_view
    return operation.run(request, *a, **kw)
  File "/Users/neo1/PycharmProjects/vec4irltr/venv/lib/python3.8/site-packages/ninja/operation.py", line 59, in run
    result = self.view_func(request, **values)
  File "/Users/neo1/PycharmProjects/vec4irltr/app/api.py", line 56, in search
    query_results = IRM.get_query_results(q=q, retrievals=RETRIEVALS, columns=columns, k=10)
AttributeError: 'NoneType' object has no attribute 'get_query_results'
