[2021-01-23 12:52:48,516] WARNING: Not Found: /api/docs/
[2021-01-23 12:52:48,800] WARNING: Not Found: /favicon.ico
[2021-01-23 12:54:12,627] WARNING: Not Found: /api/docs/
[2021-01-23 12:54:16,018] WARNING: Not Found: /api/
[2021-01-23 12:55:21,985] WARNING: Not Found: /api/search/
[2021-01-23 12:55:39,672] WARNING: Not Found: /api/docs/
[2021-01-23 12:55:44,937] WARNING: Not Found: /api2/docs/
[2021-01-23 12:55:56,606] WARNING: Not Found: /api/
[2021-01-23 12:56:02,070] WARNING: Not Found: /api/search/
[2021-01-23 12:56:16,470] WARNING: Not Found: /api/add/
[2021-01-23 12:56:40,320] WARNING: Unprocessable Entity: /api/add
[2021-01-23 12:57:00,821] WARNING: Unprocessable Entity: /api/search
[2021-01-23 12:57:13,918] ERROR: Internal Server Error: /api/search
Traceback (most recent call last):
  File "/Users/neo1/PycharmProjects/vec4irltr/venv/lib/python3.8/site-packages/django/core/handlers/exception.py", line 34, in inner
    response = get_response(request)
  File "/Users/neo1/PycharmProjects/vec4irltr/venv/lib/python3.8/site-packages/django/core/handlers/base.py", line 126, in _get_response
    response = self.process_exception_by_middleware(e, request)
  File "/Users/neo1/PycharmProjects/vec4irltr/venv/lib/python3.8/site-packages/django/core/handlers/base.py", line 124, in _get_response
    response = wrapped_callback(request, *callback_args, **callback_kwargs)
  File "/Users/neo1/PycharmProjects/vec4irltr/venv/lib/python3.8/site-packages/ninja/operation.py", line 227, in _sync_view
    return operation.run(request, *a, **kw)
  File "/Users/neo1/PycharmProjects/vec4irltr/venv/lib/python3.8/site-packages/ninja/operation.py", line 59, in run
    result = self.view_func(request, **values)
  File "/Users/neo1/PycharmProjects/vec4irltr/app/api.py", line 56, in search
    query_results = RETRIEVALS.get_query_results(q=q, retrievals=RETRIEVALS, columns=columns, k=10)
AttributeError: 'dict' object has no attribute 'get_query_results'
